Workbook
Name Beheerproces: Lijsten!$C$16:$C$25
Name Implementatieproces: Lijsten!$C$36:$C$44
Name Ontwerpproces: Lijsten!$C$45:$C$52
Name Overig: Lijsten!$C$90
Name Requirementsanalyseproces: Lijsten!$C$53:$C$63
Name Scrumproces: Lijsten!$C$64:$C$89
Name Testproces: Lijsten!$C$26:$C$35

Sheet Invulinstructie
N2: Namenlijst
B3: Welkom bij het tijdschrijf formulier voor het OOSDD Project | N3: Tim
N4: Edward
B5: Voor de start van het project | N5: Kai
B6: 1. Namenlijst | N6: Nicky
B7: Om met dit tijdschrijfformulier te beginnen dien je eerst de namen van de projectleden in de namenlijst te zetten. | N7: Rick
B8: Deze namenlijst vind je hier.
B9: Vervang de namen van de docenten door de namen van je eigen teamleden
B11: 2. Uren leegmaken
B12: Controleer of er geen voorbeeldinput staat op de Uren tab.
B13: Als deze er wel staat, gooi deze tabel leeg, alleen de blauwe kolommen!!
B15: Tijdens het project
B16: Als je werkzaamheden gedaan hebt voor het project registreer je deze op het uren tab.
B17: 1. Selecteer je naam uit de dropdown
B18: 2. Selecteer voor bij welk proces de werkzaamheden horen
B19: 3. Selecter de vaardigheid waar de werkzaamheden onder vallen
B20: 4. Geef een omschrijving van de werkzaamheden
B21: 5. Vul de datum in
... B29: Heb je meerdere taken gedaan op 1 dag? Vul deze dan allemaal los in, zo kan je bij de samenvatttingen mooi zien waar je tijd aan besteed is.

Sheet Uren
B3: Naam | C3: Proces | D3: Vaardigheid | E3: Omschrijving werkzaamheden | F3: Datum | G3: Uren | H3: Sprint nr | I3: Activiteit
B4: Edward | C4: Requirementsanalyseproces | D4: Bestuderen probleemstelling | E4: Analyse projectomschrijving en de oplossingsmogelijkheden | F4: 45971 | G4: 0.5 | H4: Sprint 0 | I4: =_xlfn.XLOOKUP(Timeform[[#This Row],[Vaardigheid]],Lijsten!C:C,Lijsten!A:A) -> Analyseren
B5: Edward | C5: Requirementsanalyseproces | D5: Beschrijven stakeholders | E5: Analyse van de users en hun behoeftes & de stakeholders | F5: 45971 | G5: 1 | H5: Sprint 0 | I5: =_xlfn.XLOOKUP(Timeform[[#This Row],[Vaardigheid]],Lijsten!C:C,Lijsten!A:A) -> Analyseren
B6: Edward | C6: Requirementsanalyseproces | D6: Uitvragen requirements | E6: Opstellen van requirements | F6: 45971 | G6: 0.5 | H6: Sprint 0 | I6: =_xlfn.XLOOKUP(Timeform[[#This Row],[Vaardigheid]],Lijsten!C:C,Lijsten!A:A) -> Analyseren
B7: Edward | C7: Requirementsanalyseproces | D7: Prioriteren requirements | E7: Opstellen van requirements | F7: 45971 | G7: 0.5 | H7: Sprint 0 | I7: =_xlfn.XLOOKUP(Timeform[[#This Row],[Vaardigheid]],Lijsten!C:C,Lijsten!A:A) -> Analyseren
B8: Edward | C8: Requirementsanalyseproces | D8: Vastleggen requirements | E8: Opstellen van requirements | F8: 45971 | G8: 1 | H8: Sprint 0 | I8: =_xlfn.XLOOKUP(Timeform[[#This Row],[Vaardigheid]],Lijsten!C:C,Lijsten!A:A) -> Analyseren
B9: Edward | C9: Requirementsanalyseproces | D9: Opsplitsen functionele en non-functionele requirements | E9: Opstellen van requirements | F9: 45971 | G9: 0.5 | H9: Sprint 0 | I9: =_xlfn.XLOOKUP(Timeform[[#This Row],[Vaardigheid]],Lijsten!C:C,Lijsten!A:A) -> Analyseren
B10: Edward | C10: Requirementsanalyseproces | D10: Maken domeinmodel | E10: Opstellen van het Functioneel ontwerp | F10: 45971 | G10: 1.5 | H10: Sprint 0 | I10: =_xlfn.XLOOKUP(Timeform[[#This Row],[Vaardigheid]],Lijsten!C:C,Lijsten!A:A) -> Analyseren
B11: Tim | C11: Scrumproces | D11: Communicatie opzetten | E11: Discord maken, inrichten, iedereen toevoegen | F11: 45971 | G11: 0.5 | H11: Sprint 0 | I11: =_xlfn.XLOOKUP(Timeform[[#This Row],[Vaardigheid]],Lijsten!C:C,Lijsten!A:A) -> Manage & Control
B12: Tim | C12: Scrumproces | D12: Aangeven behoeften | E12: Scrumworkshop gevolgd | F12: 45972 | G12: 3 | H12: Sprint 0 | I12: =_xlfn.XLOOKUP(Timeform[[#This Row],[Vaardigheid]],Lijsten!C:C,Lijsten!A:A) -> Manage & Control
B13: Edward | C13: Scrumproces | D13: Aangeven behoeften | E13: Scrumworkshop gevolgd | F13: 45972 | G13: 3 | H13: Sprint 0 | I13: =_xlfn.XLOOKUP(Timeform[[#This Row],[Vaardigheid]],Lijsten!C:C,Lijsten!A:A) -> Manage & Control
B14: Kai | C14: Scrumproces | D14: Aangeven behoeften | E14: Scrumworkshop gevolgd | F14: 45972 | G14: 3 | H14: Sprint 0 | I14: =_xlfn.XLOOKUP(Timeform[[#This Row],[Vaardigheid]],Lijsten!C:C,Lijsten!A:A) -> Manage & Control
B15: Tim | C15: Beheerproces | D15: Fork maken | E15: Git aangemaakt | F15: 45972 | G15: 1 | H15: Sprint 0 | I15: =_xlfn.XLOOKUP(Timeform[[#This Row],[Vaardigheid]],Lijsten!C:C,Lijsten!A:A) -> Manage & Control
... B31: Tim | C31: Beheerproces | D31: PO gesprek inplannen | E31: Gesprek voor deze week | F31: 45973 | G31: 0.35 | H31: Sprint 0 | I31: =_xlfn.XLOOKUP(Timeform[[#This Row],[Vaardigheid]],Lijsten!C:C,Lijsten!A:A) -> Realiseren
B32: Tim | C32: Scrumproces | D32: Reviewen werk | E32: Review alle documentatie van Edward | F32: 45974 | G32: 2 | H32: Sprint 0 | I32: Realiseren
B33: Tim | C33: Scrumproces | D33: Feedback geven | E33: Feedback geven gebaseert op review | F33: 45974 | G33: 0.5 | H33: Sprint 0 | I33: =_xlfn.XLOOKUP(Timeform[[#This Row],[Vaardigheid]],Lijsten!C:C,Lijsten!A:A) -> Adviseren
B34: Edward | C34: Scrumproces | D34: Feedback ontvangen | E34: Review en discussie mbt Feedback team | F34: 45974 | G34: 0.5 | H34: Sprint 0 | I34: =_xlfn.XLOOKUP(Timeform[[#This Row],[Vaardigheid]],Lijsten!C:C,Lijsten!A:A) -> Adviseren
B35: Edward | C35: Requirementsanalyseproces | D35: Maken domeinmodel | E35: Aanpassen en verrijken van het Functioneel ontwerp | F35: 45974 | G35: 3.5 | H35: Sprint 0 | I35: =_xlfn.XLOOKUP(Timeform[[#This Row],[Vaardigheid]],Lijsten!C:C,Lijsten!A:A) -> Analyseren
B36: Nicky | C36: Scrumproces | D36: Noteren actiepunten | E36: Notities opstellen in de requirement analyse | F36: 45974 | G36: 2.5 | H36: Sprint 0 | I36: =_xlfn.XLOOKUP(Timeform[[#This Row],[Vaardigheid]],Lijsten!C:C,Lijsten!A:A) -> Adviseren
B37: Nicky | C37: Scrumproces | D37: Reviewen werk | E37: Reviewen van alle documenten | F37: 45975 | G37: 1 | H37: Sprint 0 | I37: =_xlfn.XLOOKUP(Timeform[[#This Row],[Vaardigheid]],Lijsten!C:C,Lijsten!A:A) -> Realiseren
B38: Edward | C38: Scrumproces | D38: Feedback verwerken | E38: Opstellen van het Projectdocument | F38: 45975 | G38: 2.5 | H38: Sprint 0 | I38: =_xlfn.XLOOKUP(Timeform[[#This Row],[Vaardigheid]],Lijsten!C:C,Lijsten!A:A) -> Adviseren
B39: Tim | C39: Scrumproces | D39: Prioriteren productbacklog | E39: Prioriteiten aanpassen | F39: 45975 | G39: 0.5 | H39: Sprint 0 | I39: =_xlfn.XLOOKUP(Timeform[[#This Row],[Vaardigheid]],Lijsten!C:C,Lijsten!A:A) -> Analyseren
B40: Tim | C40: Scrumproces | D40: Reviewen werk | E40: Review projectdocument | F40: 45975 | G40: 0.75 | H40: Sprint 0 | I40: =_xlfn.XLOOKUP(Timeform[[#This Row],[Vaardigheid]],Lijsten!C:C,Lijsten!A:A) -> Realiseren
B41: Tim | C41: Beheerproces | D41: Maken geversioneerde release | E41: Documenten klaarzetten voor release sprint 0 | F41: 45975 | G41: 0.75 | H41: Sprint 0 | I41: =_xlfn.XLOOKUP(Timeform[[#This Row],[Vaardigheid]],Lijsten!C:C,Lijsten!A:A) -> Realiseren
B42: Edward | C42: Scrumproces | D42: Reviewen werk | E42: Review Sprint 0 aan teamleden | F42: 45975 | G42: 0.75 | H42: Sprint 0 | I42: =_xlfn.XLOOKUP(Timeform[[#This Row],[Vaardigheid]],Lijsten!C:C,Lijsten!A:A) -> Realiseren
B43: Tim | C43: Beheerproces | D43: Doorvoeren PR naar main | E43: Git merge (documentatie) | F43: 45975 | G43: 0.3 | H43: Sprint 0 | I43: =_xlfn.XLOOKUP(Timeform[[#This Row],[Vaardigheid]],Lijsten!C:C,Lijsten!A:A) -> Realiseren
B44: Tim | C44: Beheerproces | D44: Doorvoeren PR naar main | E44: Git merge (testontwerp) | F44: 45975 | G44: 0.3 | H44: Sprint 0 | I44: =_xlfn.XLOOKUP(Timeform[[#This Row],[Vaardigheid]],Lijsten!C:C,Lijsten!A:A) -> Realiseren
... B371: Tim | C371: Scrumproces | D371: Kiezen user stories | E371: User stories sorteren en verbeteren | F371: 46008 | G371: 0.75 | H371: Sprint 3 | I371: =_xlfn.XLOOKUP(Timeform[[#This Row],[Vaardigheid]],Lijsten!C:C,Lijsten!A:A) -> Analyseren
B372: Tim | E372: ziek | F372: 46008 | H372: Sprint 3 | I372: =_xlfn.XLOOKUP(Timeform[[#This Row],[Vaardigheid]],Lijsten!C:C,Lijsten!A:A) -> 0
B373: Kai | C373: Implementatieproces | D373: Structureer code | E373: beste wpm gemaakt 1/2 | F373: 46008 | G373: 1 | H373: Sprint 3 | I373: =_xlfn.XLOOKUP(Timeform[[#This Row],[Vaardigheid]],Lijsten!C:C,Lijsten!A:A) -> Realiseren
B374: Nicky | C374: Scrumproces | D374: Toevoegen taken aan user story | E374: Toevoegen taken aan user story | F374: 46008 | G374: 0.75 | H374: Sprint 3 | I374: =_xlfn.XLOOKUP(Timeform[[#This Row],[Vaardigheid]],Lijsten!C:C,Lijsten!A:A) -> Analyseren
B375: Edward | C375: Scrumproces | D375: Toevoegen taken aan user story | E375: Toevoegen verschillende user stories aan Epic's | F375: 46008 | G375: 0.5 | H375: Sprint 3 | I375: =_xlfn.XLOOKUP(Timeform[[#This Row],[Vaardigheid]],Lijsten!C:C,Lijsten!A:A) -> Analyseren
B376: Nicky | C376: Scrumproces | D376: Daily standup | E376: Dailystandup | F376: 46008 | G376: 0.5 | H376: Sprint 3 | I376: =_xlfn.XLOOKUP(Timeform[[#This Row],[Vaardigheid]],Lijsten!C:C,Lijsten!A:A) -> Manage & Control
B377: Nicky | C377: Scrumproces | D377: Reviewen werk | E377: Reviewen werk en aanpassen | F377: 46008 | G377: 2 | H377: Sprint 3 | I377: =_xlfn.XLOOKUP(Timeform[[#This Row],[Vaardigheid]],Lijsten!C:C,Lijsten!A:A) -> Realiseren
B378: Nicky | C378: Testproces | D378: Uitvoeren handmatige test | E378: Uitvoeren na merge | F378: 46008 | G378: 0.5 | H378: Sprint 3 | I378: =_xlfn.XLOOKUP(Timeform[[#This Row],[Vaardigheid]],Lijsten!C:C,Lijsten!A:A) -> Realiseren
B379: Nicky | C379: Beheerproces | D379: Inrichten .gitignore | E379: .gitignore aanpassen (teveel local files) | F379: 46008 | G379: 0.5 | H379: Sprint 3 | I379: =_xlfn.XLOOKUP(Timeform[[#This Row],[Vaardigheid]],Lijsten!C:C,Lijsten!A:A) -> Manage & Control
B380: Tim | C380: Scrumproces | D380: Daily standup | E380: Daily standup als scrummaster gehouden | F380: 46009 | G380: 0.5 | H380: Sprint 3 | I380: =_xlfn.XLOOKUP(Timeform[[#This Row],[Vaardigheid]],Lijsten!C:C,Lijsten!A:A) -> Manage & Control
B381: Tim | C381: Scrumproces | D381: Ondersteunen teamlid | E381: Hulp met merge | F381: 46009 | G381: 0.75 | H381: Sprint 3 | I381: =_xlfn.XLOOKUP(Timeform[[#This Row],[Vaardigheid]],Lijsten!C:C,Lijsten!A:A) -> Adviseren
B382: Tim | E382: ziek | F382: 46009 | H382: Sprint 3 | I382: =_xlfn.XLOOKUP(Timeform[[#This Row],[Vaardigheid]],Lijsten!C:C,Lijsten!A:A) -> 0
B383: Kai | C383: Scrumproces | D383: Daily standup | E383: Daily standup | F383: 46009 | G383: 1 | H383: Sprint 3 | I383: =_xlfn.XLOOKUP(Timeform[[#This Row],[Vaardigheid]],Lijsten!C:C,Lijsten!A:A) -> Manage & Control
...

Sheet Lijsten
A2: Namenlijst
A3: Tim
A4: Edward
A5: Kai
A6: Nicky
A7: Rick
A15: Activiteit | B15: Proces | C15: Vaardigheid
A16: Manage & Control | B16: Beheerproces | C16: Fork maken
A17: Manage & Control | B17: Beheerproces | C17: Testen in pipeline
A18: Manage & Control | B18: Beheerproces | C18: Inrichten .gitignore
A19: Realiseren | B19: Beheerproces | C19: Mergen feature met PR
A20: Realiseren | B20: Beheerproces | C20: Maken geversioneerde release
A21: Realiseren | B21: Beheerproces | C21: Kiezen branchingstrategie
A22: Realiseren | B22: Beheerproces | C22: Maken feature branch
A23: Realiseren | B23: Beheerproces | C23: Opzetten testen in pipeline
A24: Realiseren | B24: Beheerproces | C24: Doorvoeren PR naar dev
A25: Realiseren | B25: Beheerproces | C25: Doorvoeren PR naar main
A26: Manage & Control | B26: Beheerproces | C26: Inlevering klaarmaken
... A92: Adviseren | B92: Testproces | C92: Evalueren testresultaat

Sheet Samenvattingen
B2: Verdeling over proces stappen | E2: Verdeling over HBO-I activiteiten
B3: Naam en Sprint | C3: Sum of Uren | E3: Naam en Sprint | F3: Sum of Uren
B4: Edward | C4: 146.1 | E4: Edward | F4: 146.1
B5: Sprint 0 | C5: 25.25 | E5: Sprint 0 | F5: 25.25
B6: Ontwerpproces | C6: 2 | E6: Analyseren | F6: 9
B7: Requirementsanalyseproces | C7: 11 | E7: Manage & Control | F7: 5
B8: Testproces | C8: 3.5 | E8: Realiseren | F8: 2.25
B9: Scrumproces | C9: 8.75 | E9: Ontwerpen | F9: 4
B10: Sprint 1 | C10: 22.55 | E10: Adviseren | F10: 5
B11: Implementatieproces | C11: 4 | E11: Sprint 1 | F11: 22.55
B12: Ontwerpproces | C12: 8 | E12: Analyseren | F12: 5
B13: Requirementsanalyseproces | C13: 2 | E13: Manage & Control | F13: 1
B14: Scrumproces | C14: 8.55 | E14: Realiseren | F14: 4.5
B15: Sprint 2 | C15: 51.5 | E15: Ontwerpen | F15: 8
... B48: Scrumproces | C48: 15.75 | E48: Sprint 3 | F48: 43.55
B49: Nicky | C49: 100.75 | E49: 0
B50: Sprint 0 | C50: 7.5 | E50: Analyseren | F50: 1.9
B51: Requirementsanalyseproces | C51: 1 | E51: Manage & Control | F51: 17.4
B52: Scrumproces | C52: 6.5 | E52: Realiseren | F52: 9.25
B53: Sprint 1 | C53: 12.75 | E53: Ontwerpen | F53: 9.25
B54: Implementatieproces | C54: 3.5 | E54: Adviseren | F54: 5.75
B55: Scrumproces | C55: 7 | E55: Kai | F55: 93.2
B56: Adviseren | C56: 2.25 | E56: Sprint 0 | F56: 3.5
B57: Sprint 2 | C57: 32 | E57: Manage & Control | F57: 3
B58: Implementatieproces | C58: 15 | E58: Adviseren | F58: 0.5
B59: Requirementsanalyseproces | C59: 6 | E59: Sprint 1 | F59: 19.3
B60: Scrumproces | C60: 11 | E60: Analyseren | F60: 6.5
B61: Sprint 3 | C61: 48.5 | E61: Manage & Control | F61: 1
... B95: Ontwerpproces | C95: 6 | E95: Adviseren | F95: 1.5
B96: (leeg) | E96: Rick | F96: 8.5
B97: Testproces | C97: 5.1 | E97: Sprint 2 | F97: 8.5
B98: Scrumproces | C98: 17.55 | E98: Realiseren | F98: 8.5
B99: Eindtotaal | C99: 488.25 | E99: Eindtotaal | F99: 488.25
